Workbook

Sheet Table A2
D4: Table A2
F5: Weekly Consumption in Control Households | P5: Impact of Conditional Cash Transfer: | Z5: Averages from Tab FAO Data A2 (Converted to Kgs)
D6: Food Item | E6: Elasticity | F6: Kg | G6: Calories | H6: Carbs (g) | I6: Protein (g) | J6: Fat (g) | K6: Fiber (g) | L6: Ash (g) | M6: Calcium (mg) | N6: Iron (mg) | O6: Vit C (mg) | P6: Calories | Q6: Carbs (g) | R6: Protein (g) | S6: Fat (g) | T6: Fiber (g) | U6: Ash (g) | V6: Calcium (mg) | W6: Iron (mg) | X6: Vit C (mg) | Z6: Calories | AA6: Carbs (g) | AB6: Protein (g) | AC6: Fat (g) | AD6: Fiber (g) | AE6: Ash (g) | AF6: Calcium (mg) | AG6: Iron (mg) | AH6: Vit C (mg)
D7: Staples
D8: Corn | E8: 0.001 | F8: 10.26 | G8: =$F8*Z8 -> 30343.95 | H8: =$F8*AA8 -> 6117.7815 | I8: =$F8*AB8 -> 798.228 | J8: =$F8*AC8 -> 385.263 | K8: =$F8*AD8 -> 755.82 | L8: =$F8*AE8 -> 110.295 | M8: =$F8*AF8 -> 974.7 | N8: =$F8*AG8 -> 304.209 | O8: =$F8*AH8 -> 436.05 | P8: =$E8*G8 -> 30.34395 | Q8: =$E8*H8 -> 6.1177815 | R8: =$E8*I8 -> 0.798228 | S8: =$E8*J8 -> 0.385263 | T8: =$E8*K8 -> 0.75582 | U8: =$E8*L8 -> 0.110295 | V8: =$E8*M8 -> 0.9747 | W8: =$E8*N8 -> 0.304209 | X8: =$E8*O8 -> 0.43605 | Z8: =10*(AVERAGE('FAO Data A2'!J27:J30)) -> 2957.5 | AA8: =10*(AVERAGE('FAO Data A2'!K27:K30)) -> 596.275 | AB8: =10*(AVERAGE('FAO Data A2'!L27:L30)) -> 77.8 | AC8: =10*(AVERAGE('FAO Data A2'!M27:M30)) -> 37.55 | AD8: =10*(AVERAGE('FAO Data A2'!N27:N30)) -> 73.666667 | AE8: =10*(AVERAGE('FAO Data A2'!O27:O30)) -> 10.75 | AF8: =10*(AVERAGE('FAO Data A2'!P27:P30)) -> 95 | AG8: =10*(AVERAGE('FAO Data A2'!Q27:Q30)) -> 29.65 | AH8: =10*(AVERAGE('FAO Data A2'!R27:R30)) -> 42.5
D9: Rice | E9: 0.156 | F9: 0.57 | G9: =$F9*Z9 -> 2052 | H9: =$F9*AA9 -> 454.2045 | I9: =$F9*AB9 -> 39.28725 | J9: =$F9*AC9 -> 3.06375 | K9: =$F9*AD9 -> 3.99 | L9: =$F9*AE9 -> 3.17775 | M9: =$F9*AF9 -> 86.2125 | N9: =$F9*AG9 -> 6.59775 | O9: =$F9*AH9 -> 0 | P9: =$E9*G9 -> 320.112 | Q9: =$E9*H9 -> 70.855902 | R9: =$E9*I9 -> 6.128811 | S9: =$E9*J9 -> 0.477945 | T9: =$E9*K9 -> 0.62244 | U9: =$E9*L9 -> 0.495729 | V9: =$E9*M9 -> 13.44915 | W9: =$E9*N9 -> 1.029249 | X9: =$E9*O9 -> 0 | Z9: =10*(AVERAGE('FAO Data A2'!J35:J38)) -> 3600 | AA9: =10*(AVERAGE('FAO Data A2'!K35:K38)) -> 796.85 | AB9: =10*(AVERAGE('FAO Data A2'!L35:L38)) -> 68.925 | AC9: =10*(AVERAGE('FAO Data A2'!M35:M38)) -> 5.375 | AD9: =10*(AVERAGE('FAO Data A2'!N35:N38)) -> 7 | AE9: =10*(AVERAGE('FAO Data A2'!O35:O38)) -> 5.575 | AF9: =10*(AVERAGE('FAO Data A2'!P35:P38)) -> 151.25 | AG9: =10*(AVERAGE('FAO Data A2'!Q35:Q38)) -> 11.575 | AH9: =10*(AVERAGE('FAO Data A2'!R35:R38)) -> 0
D10: Bread | E10: 0.327 | F10: 0.28 | G10: =$F10*Z10 -> 774.9 | H10: =$F10*AA10 -> 141.386 | I10: =$F10*AB10 -> 25.634 | J10: =$F10*AC10 -> 9.9773333 | K10: =$F10*AD10 -> 8.0266667 | L10: =$F10*AE10 -> 5.292 | M10: =$F10*AF10 -> 265.3 | N10: =$F10*AG10 -> 28.868 | O10: =$F10*AH10 -> 0 | P10: =$E10*G10 -> 253.3923 | Q10: =$E10*H10 -> 46.233222 | R10: =$E10*I10 -> 8.382318 | S10: =$E10*J10 -> 3.262588 | T10: =$E10*K10 -> 2.62472 | U10: =$E10*L10 -> 1.730484 | V10: =$E10*M10 -> 86.7531 | W10: =$E10*N10 -> 9.439836 | X10: =$E10*O10 -> 0 | Z10: =10*(AVERAGE('FAO Data A2'!J31:J34)) -> 2767.5 | AA10: =10*(AVERAGE('FAO Data A2'!K31:K34)) -> 504.95 | AB10: =10*(AVERAGE('FAO Data A2'!L31:L34)) -> 91.55 | AC10: =10*(AVERAGE('FAO Data A2'!M31:M34)) -> 35.633333 | AD10: =10*(AVERAGE('FAO Data A2'!N31:N34)) -> 28.666667 | AE10: =10*(AVERAGE('FAO Data A2'!O31:O34)) -> 18.9 | AF10: =10*(AVERAGE('FAO Data A2'!P31:P34)) -> 947.5 | AG10: =10*(AVERAGE('FAO Data A2'!Q31:Q34)) -> 103.1 | AH10: =10*(AVERAGE('FAO Data A2'!R31:R34)) -> 0
D11: Potato | E11: 0.34 | F11: 0.49 | G11: =$F11*Z11 -> 373.625 | H11: =$F11*AA11 -> 85.19875 | I11: =$F11*AB11 -> 9.56725 | J11: =$F11*AC11 -> 1.43325 | K11: =$F11*AD11 -> 8.085 | L11: =$F11*AE11 -> 5.782 | M11: =$F11*AF11 -> 61.16425 | N11: =$F11*AG11 -> 6.713 | O11: =$F11*AH11 -> 102.64275 | P11: =$E11*G11 -> 127.0325 | Q11: =$E11*H11 -> 28.967575 | R11: =$E11*I11 -> 3.252865 | S11: =$E11*J11 -> 0.487305 | T11: =$E11*K11 -> 2.7489 | U11: =$E11*L11 -> 1.96588 | V11: =$E11*M11 -> 20.795845 | W11: =$E11*N11 -> 2.28242 | X11: =$E11*O11 -> 34.898535 | Z11: =10*(AVERAGE('FAO Data A2'!J39:J42)) -> 762.5 | AA11: =10*(AVERAGE('FAO Data A2'!K39:K42)) -> 173.875 | AB11: =10*(AVERAGE('FAO Data A2'!L39:L42)) -> 19.525 | AC11: =10*(AVERAGE('FAO Data A2'!M39:M42)) -> 2.925 | AD11: =10*(AVERAGE('FAO Data A2'!N39:N42)) -> 16.5 | AE11: =10*(AVERAGE('FAO Data A2'!O39:O42)) -> 11.8 | AF11: =10*(AVERAGE('FAO Data A2'!P39:P42)) -> 124.825 | AG11: =10*(AVERAGE('FAO Data A2'!Q39:Q42)) -> 13.7 | AH11: =10*(AVERAGE('FAO Data A2'!R39:R42)) -> 209.475
D12: Protein
D13: Chicken | E13: 0.417 | F13: 0.43 | G13: =$F13*Z13 -> 689.075 | H13: =$F13*AA13 -> 0 | I13: =$F13*AB13 -> 86.59125 | J13: =$F13*AC13 -> 34.60425 | K13: =$F13*AD13 -> 0 | L13: =$F13*AE13 -> 4.20325 | M13: =$F13*AF13 -> 43.82775 | N13: =$F13*AG13 -> 10.148 | O13: =$F13*AH13 -> 1.075 | P13: =$E13*G13 -> 287.34427 | Q13: =$E13*H13 -> 0 | R13: =$E13*I13 -> 36.108551 | S13: =$E13*J13 -> 14.429972 | T13: =$E13*K13 -> 0 | U13: =$E13*L13 -> 1.7527552 | V13: =$E13*M13 -> 18.276172 | W13: =$E13*N13 -> 4.231716 | X13: =$E13*O13 -> 0.448275 | Z13: =10*(AVERAGE('FAO Data A2'!J3:J6)) -> 1602.5 | AA13: =10*(AVERAGE('FAO Data A2'!K3:K6)) -> 0 | AB13: =10*(AVERAGE('FAO Data A2'!L3:L6)) -> 201.375 | AC13: =10*(AVERAGE('FAO Data A2'!M3:M6)) -> 80.475 | AD13: =10*(AVERAGE('FAO Data A2'!N3:N6)) -> 0 | AE13: =10*(AVERAGE('FAO Data A2'!O3:O6)) -> 9.775 | AF13: =10*(AVERAGE('FAO Data A2'!P3:P6)) -> 101.925 | AG13: =10*(AVERAGE('FAO Data A2'!Q3:Q6)) -> 23.6 | AH13: =10*(AVERAGE('FAO Data A2'!R3:R6)) -> 2.5
D14: Pork | E14: 0.193 | F14: 0.2 | G14: =$F14*Z14 -> 427 | H14: =$F14*AA14 -> 0 | I14: =$F14*AB14 -> 38.3 | J14: =$F14*AC14 -> 29.785 | K14: =$F14*AD14 -> 0 | L14: =$F14*AE14 -> 2.095 | M14: =$F14*AF14 -> 12.5 | N14: =$F14*AG14 -> 2.245 | O14: =$F14*AH14 -> 0 | P14: =$E14*G14 -> 82.411 | Q14: =$E14*H14 -> 0 | R14: =$E14*I14 -> 7.3919 | S14: =$E14*J14 -> 5.748505 | T14: =$E14*K14 -> 0 | U14: =$E14*L14 -> 0.404335 | V14: =$E14*M14 -> 2.4125 | W14: =$E14*N14 -> 0.433285 | X14: =$E14*O14 -> 0 | Z14: =10*(AVERAGE('FAO Data A2'!J7:J10)) -> 2135 | AA14: =10*(AVERAGE('FAO Data A2'!K7:K10)) -> 0 | AB14: =10*(AVERAGE('FAO Data A2'!L7:L10)) -> 191.5 | AC14: =10*(AVERAGE('FAO Data A2'!M7:M10)) -> 148.925 | AD14: =10*(AVERAGE('FAO Data A2'!N7:N10)) -> 0 | AE14: =10*(AVERAGE('FAO Data A2'!O7:O10)) -> 10.475 | AF14: =10*(AVERAGE('FAO Data A2'!P7:P10)) -> 62.5 | AG14: =10*(AVERAGE('FAO Data A2'!Q7:Q10)) -> 11.225 | AH14: =10*(AVERAGE('FAO Data A2'!R7:R10)) -> 0
D15: Beef | E15: 0.235 | F15: 0.21 | G15: =$F15*Z15 -> 372.75 | H15: =$F15*AA15 -> 1.5225 | I15: =$F15*AB15 -> 39.18075 | J15: =$F15*AC15 -> 21.96075 | K15: =$F15*AD15 -> 0 | L15: =$F15*AE15 -> 3.10275 | M15: =$F15*AF15 -> 23.1 | N15: =$F15*AG15 -> 6.52575 | O15: =$F15*AH15 -> 0 | P15: =$E15*G15 -> 87.59625 | Q15: =$E15*H15 -> 0.3577875 | R15: =$E15*I15 -> 9.2074762 | S15: =$E15*J15 -> 5.1607762 | T15: =$E15*K15 -> 0 | U15: =$E15*L15 -> 0.72914625 | V15: =$E15*M15 -> 5.4285 | W15: =$E15*N15 -> 1.5335512 | X15: =$E15*O15 -> 0 | Z15: =10*(AVERAGE('FAO Data A2'!J59:J62)) -> 1775 | AA15: =10*(AVERAGE('FAO Data A2'!K59:K62)) -> 7.25 | AB15: =10*(AVERAGE('FAO Data A2'!L59:L62)) -> 186.575 | AC15: =10*(AVERAGE('FAO Data A2'!M59:M62)) -> 104.575 | AD15: =10*(AVERAGE('FAO Data A2'!N59:N62)) -> 0 | AE15: =10*(AVERAGE('FAO Data A2'!O59:O62)) -> 14.775 | AF15: =10*(AVERAGE('FAO Data A2'!P59:P62)) -> 110 | AG15: =10*(AVERAGE('FAO Data A2'!Q59:Q62)) -> 31.075 | AH15: =10*(AVERAGE('FAO Data A2'!R59:R62)) -> 0
D16: Fish | E16: 0.068 | F16: 0.05 | G16: =$F16*Z16 -> 50.75 | H16: =$F16*AA16 -> 0 | I16: =$F16*AB16 -> 8.46375 | J16: =$F16*AC16 -> 1.565 | K16: =$F16*AD16 -> 0 | L16: =$F16*AE16 -> 0.5275 | M16: =$F16*AF16 -> 15.875 | N16: =$F16*AG16 -> 0.34125 | O16: =$F16*AH16 -> 0.33333333 | P16: =$E16*G16 -> 3.451 | Q16: =$E16*H16 -> 0 | R16: =$E16*I16 -> 0.575535 | S16: =$E16*J16 -> 0.10642 | T16: =$E16*K16 -> 0 | U16: =$E16*L16 -> 0.03587 | V16: =$E16*M16 -> 1.0795 | W16: =$E16*N16 -> 0.023205 | X16: =$E16*O16 -> 0.022666667 | Z16: =10*(AVERAGE('FAO Data A2'!J15:J18)) -> 1015 | AA16: =10*(AVERAGE('FAO Data A2'!K15:K18)) -> 0 | AB16: =10*(AVERAGE('FAO Data A2'!L15:L18)) -> 169.275 | AC16: =10*(AVERAGE('FAO Data A2'!M15:M18)) -> 31.3 | AD16: =10*(AVERAGE('FAO Data A2'!N15:N18)) -> 0 | AE16: =10*(AVERAGE('FAO Data A2'!O15:O18)) -> 10.55 | AF16: =10*(AVERAGE('FAO Data A2'!P15:P18)) -> 317.5 | AG16: =10*(AVERAGE('FAO Data A2'!Q15:Q18)) -> 6.825 | AH16: =10*(AVERAGE('FAO Data A2'!R15:R18)) -> 6.6666667
D17: Eggs | E17: 0.209 | F17: 0.82 | G17: =$F17*Z17 -> 1211.55 | H17: =$F17*AA17 -> 15.99 | I17: =$F17*AB17 -> 102.254 | J17: =$F17*AC17 -> 80.647 | K17: =$F17*AD17 -> 0 | L17: =$F17*AE17 -> 8.528 | M17: =$F17*AF17 -> 410.697 | N17: =$F17*AG17 -> 18.409 | O17: =$F17*AH17 -> 0 | P17: =$E17*G17 -> 253.21395 | Q17: =$E17*H17 -> 3.34191 | R17: =$E17*I17 -> 21.371086 | S17: =$E17*J17 -> 16.855223 | T17: =$E17*K17 -> 0 | U17: =$E17*L17 -> 1.782352 | V17: =$E17*M17 -> 85.835673 | W17: =$E17*N17 -> 3.847481 | X17: =$E17*O17 -> 0 | Z17: =10*(AVERAGE('FAO Data A2'!J19:J22)) -> 1477.5 | AA17: =10*(AVERAGE('FAO Data A2'!K19:K22)) -> 19.5 | AB17: =10*(AVERAGE('FAO Data A2'!L19:L22)) -> 124.7 | AC17: =10*(AVERAGE('FAO Data A2'!M19:M22)) -> 98.35 | AD17: =10*(AVERAGE('FAO Data A2'!N19:N22)) -> 0 | AE17: =10*(AVERAGE('FAO Data A2'!O19:O22)) -> 10.4 | AF17: =10*(AVERAGE('FAO Data A2'!P19:P22)) -> 500.85 | AG17: =10*(AVERAGE('FAO Data A2'!Q19:Q22)) -> 22.45 | AH17: =10*(AVERAGE('FAO Data A2'!R19:R22)) -> 0
D18: Milk | E18: 0.16 | F18: 0.53 | G18: =$F18*Z18 -> 357.75 | H18: =$F18*AA18 -> 24.804 | I18: =$F18*AB18 -> 17.914 | J18: =$F18*AC18 -> 23.46575 | K18: =$F18*AD18 -> 0 | L18: =$F18*AE18 -> 3.82925 | M18: =$F18*AF18 -> 638.756 | N18: =$F18*AG18 -> 4.399 | O18: =$F18*AH18 -> 2.65 | P18: =$E18*G18 -> 57.24 | Q18: =$E18*H18 -> 3.96864 | R18: =$E18*I18 -> 2.86624 | S18: =$E18*J18 -> 3.75452 | T18: =$E18*K18 -> 0 | U18: =$E18*L18 -> 0.61268 | V18: =$E18*M18 -> 102.20096 | W18: =$E18*N18 -> 0.70384 | X18: =$E18*O18 -> 0.424 | Z18: =10*(AVERAGE('FAO Data A2'!J23:J26)) -> 675 | AA18: =10*(AVERAGE('FAO Data A2'!K23:K26)) -> 46.8 | AB18: =10*(AVERAGE('FAO Data A2'!L23:L26)) -> 33.8 | AC18: =10*(AVERAGE('FAO Data A2'!M23:M26)) -> 44.275 | AD18: =10*(AVERAGE('FAO Data A2'!N23:N26)) -> 0 | AE18: =10*(AVERAGE('FAO Data A2'!O23:O26)) -> 7.225 | AF18: =10*(AVERAGE('FAO Data A2'!P23:P26)) -> 1205.2 | AG18: =10*(AVERAGE('FAO Data A2'!Q23:Q26)) -> 8.3 | AH18: =10*(AVERAGE('FAO Data A2'!R23:R26)) -> 5
D19: Beans | E19: 0.07 | F19: 1.76 | G19: =$F19*Z19 -> 6991.6 | H19: =$F19*AA19 -> 437.052 | I19: =$F19*AB19 -> 643.984 | J19: =$F19*AC19 -> 326.392 | K19: =$F19*AD19 -> 199.32 | L19: =$F19*AE19 -> 87.296 | M19: =$F19*AF19 -> 4307.6 | N19: =$F19*AG19 -> 185.02 | O19: =$F19*AH19 -> 74.8 | P19: =$E19*G19 -> 489.412 | Q19: =$E19*H19 -> 30.59364 | R19: =$E19*I19 -> 45.07888 | S19: =$E19*J19 -> 22.84744 | T19: =$E19*K19 -> 13.9524 | U19: =$E19*L19 -> 6.11072 | V19: =$E19*M19 -> 301.532 | W19: =$E19*N19 -> 12.9514 | X19: =$E19*O19 -> 5.236 | Z19: =10*(AVERAGE('FAO Data A2'!J67:J70)) -> 3972.5 | AA19: =10*(AVERAGE('FAO Data A2'!K67:K70)) -> 248.325 | AB19: =10*(AVERAGE('FAO Data A2'!L67:L70)) -> 365.9 | AC19: =10*(AVERAGE('FAO Data A2'!M67:M70)) -> 185.45 | AD19: =10*(AVERAGE('FAO Data A2'!N67:N70)) -> 113.25 | AE19: =10*(AVERAGE('FAO Data A2'!O67:O70)) -> 49.6 | AF19: =10*(AVERAGE('FAO Data A2'!P67:P70)) -> 2447.5 | AG19: =10*(AVERAGE('FAO Data A2'!Q67:Q70)) -> 105.125 | AH19: =10*(AVERAGE('FAO Data A2'!R67:R70)) -> 42.5
D20: Vegetables & Fruits
D21: Tomato | E21: 0.174 | F21: 0.96 | G21: =$F21*Z21 -> 187.2 | H21: =$F21*AA21 -> 33.84 | I21: =$F21*AB21 -> 8.376 | J21: =$F21*AC21 -> 2.256 | K21: =$F21*AD21 -> 9.84 | L21: =$F21*AE21 -> 5.352 | M21: =$F21*AF21 -> 106.8 | N21: =$F21*AG21 -> 5.976 | O21: =$F21*AH21 -> 229.272 | P21: =$E21*G21 -> 32.5728 | Q21: =$E21*H21 -> 5.88816 | R21: =$E21*I21 -> 1.457424 | S21: =$E21*J21 -> 0.392544 | T21: =$E21*K21 -> 1.71216 | U21: =$E21*L21 -> 0.931248 | V21: =$E21*M21 -> 18.5832 | W21: =$E21*N21 -> 1.039824 | X21: =$E21*O21 -> 39.893328 | Z21: =10*(AVERAGE('FAO Data A2'!J43:J46)) -> 195 | AA21: =10*(AVERAGE('FAO Data A2'!K43:K46)) -> 35.25 | AB21: =10*(AVERAGE('FAO Data A2'!L43:L46)) -> 8.725 | AC21: =10*(AVERAGE('FAO Data A2'!M43:M46)) -> 2.35 | AD21: =10*(AVERAGE('FAO Data A2'!N43:N46)) -> 10.25 | AE21: =10*(AVERAGE('FAO Data A2'!O43:O46)) -> 5.575 | AF21: =10*(AVERAGE('FAO Data A2'!P43:P46)) -> 111.25 | AG21: =10*(AVERAGE('FAO Data A2'!Q43:Q46)) -> 6.225 | AH21: =10*(AVERAGE('FAO Data A2'!R43:R46)) -> 238.825
D22: Leafy Greens | E22: 0.056 | F22: 0.04 | G22: =$F22*Z22 -> 10.85 | H22: =$F22*AA22 -> 1.336 | I22: =$F22*AB22 -> 1.178 | J22: =$F22*AC22 -> 0.123 | K22: =$F22*AD22 -> 0.868 | L22: =$F22*AE22 -> 0.75 | M22: =$F22*AF22 -> 75.333 | N22: =$F22*AG22 -> 1.422 | O22: =$F22*AH22 -> 17.52 | P22: =$E22*G22 -> 0.6076 | Q22: =$E22*H22 -> 0.074816 | R22: =$E22*I22 -> 0.065968 | S22: =$E22*J22 -> 0.006888 | T22: =$E22*K22 -> 0.048608 | U22: =$E22*L22 -> 0.042 | V22: =$E22*M22 -> 4.218648 | W22: =$E22*N22 -> 0.079632 | X22: =$E22*O22 -> 0.98112 | Z22: =10*(AVERAGE('FAO Data A2'!J87:J90)) -> 271.25 | AA22: =10*(AVERAGE('FAO Data A2'!K87:K90)) -> 33.4 | AB22: =10*(AVERAGE('FAO Data A2'!L87:L90)) -> 29.45 | AC22: =10*(AVERAGE('FAO Data A2'!M87:M90)) -> 3.075 | AD22: =10*(AVERAGE('FAO Data A2'!N87:N90)) -> 21.7 | AE22: =10*(AVERAGE('FAO Data A2'!O87:O90)) -> 18.75 | AF22: =10*(AVERAGE('FAO Data A2'!P87:P90)) -> 1883.325 | AG22: =10*(AVERAGE('FAO Data A2'!Q87:Q90)) -> 35.55 | AH22: =10*(AVERAGE('FAO Data A2'!R87:R90)) -> 438
D23: Onion | E23: 0.149 | F23: 0.63 | G23: =$F23*Z23 -> 226.8 | H23: =$F23*AA23 -> 45.486 | I23: =$F23*AB23 -> 11.1195 | J23: =$F23*AC23 -> 1.764 | K23: =$F23*AD23 -> 13.86 | L23: =$F23*AE23 -> 4.599 | M23: =$F23*AF23 -> 355.95 | N23: =$F23*AG23 -> 9.5445 | O23: =$F23*AH23 -> 140.175 | P23: =$E23*G23 -> 33.7932 | Q23: =$E23*H23 -> 6.777414 | R23: =$E23*I23 -> 1.6568055 | S23: =$E23*J23 -> 0.262836 | T23: =$E23*K23 -> 2.06514 | U23: =$E23*L23 -> 0.685251 | V23: =$E23*M23 -> 53.03655 | W23: =$E23*N23 -> 1.4221305 | X23: =$E23*O23 -> 20.886075 | Z23: =10*(AVERAGE('FAO Data A2'!J55:J58)) -> 360 | AA23: =10*(AVERAGE('FAO Data A2'!K55:K58)) -> 72.2 | AB23: =10*(AVERAGE('FAO Data A2'!L55:L58)) -> 17.65 | AC23: =10*(AVERAGE('FAO Data A2'!M55:M58)) -> 2.8 | AD23: =10*(AVERAGE('FAO Data A2'!N55:N58)) -> 22 | AE23: =10*(AVERAGE('FAO Data A2'!O55:O58)) -> 7.3 | AF23: =10*(AVERAGE('FAO Data A2'!P55:P58)) -> 565 | AG23: =10*(AVERAGE('FAO Data A2'!Q55:Q58)) -> 15.15 | AH23: =10*(AVERAGE('FAO Data A2'!R55:R58)) -> 222.5
D24: Banana | E24: 0.244 | F24: 0.48 | G24: =$F24*Z24 -> 432 | H24: =$F24*AA24 -> 103.416 | I24: =$F24*AB24 -> 5.976 | J24: =$F24*AC24 -> 1.488 | K24: =$F24*AD24 -> 8.64 | L24: =$F24*AE24 -> 3.984 | M24: =$F24*AF24 -> 38.4 | N24: =$F24*AG24 -> 2.784 | O24: =$F24*AH24 -> 431.64 | P24: =$E24*G24 -> 105.408 | Q24: =$E24*H24 -> 25.233504 | R24: =$E24*I24 -> 1.458144 | S24: =$E24*J24 -> 0.363072 | T24: =$E24*K24 -> 2.10816 | U24: =$E24*L24 -> 0.972096 | V24: =$E24*M24 -> 9.3696 | W24: =$E24*N24 -> 0.679296 | X24: =$E24*O24 -> 105.32016 | Z24: =10*(AVERAGE('FAO Data A2'!J51:J54)) -> 900 | AA24: =10*(AVERAGE('FAO Data A2'!K51:K54)) -> 215.45 | AB24: =10*(AVERAGE('FAO Data A2'!L51:L54)) -> 12.45 | AC24: =10*(AVERAGE('FAO Data A2'!M51:M54)) -> 3.1 | AD24: =10*(AVERAGE('FAO Data A2'!N51:N54)) -> 18 | AE24: =10*(AVERAGE('FAO Data A2'!O51:O54)) -> 8.3 | AF24: =10*(AVERAGE('FAO Data A2'!P51:P54)) -> 80 | AG24: =10*(AVERAGE('FAO Data A2'!Q51:Q54)) -> 5.8 | AH24: =10*(AVERAGE('FAO Data A2'!R51:R54)) -> 899.25
D25: Other
D26: Cookies | E26: 0.8 | F26: 0.08 | G26: =$F26*Z26 -> 337.6 | H26: =$F26*AA26 -> 56.930667 | I26: =$F26*AB26 -> 7.336 | J26: =$F26*AC26 -> 8.3493333 | K26: =$F26*AD26 -> 1.36 | L26: =$F26*AE26 -> 1.2666667 | M26: =$F26*AF26 -> 113.2 | N26: =$F26*AG26 -> 2.112 | O26: =$F26*AH26 -> 0.08 | P26: =$E26*G26 -> 270.08 | Q26: =$E26*H26 -> 45.544533 | R26: =$E26*I26 -> 5.8688 | S26: =$E26*J26 -> 6.6794667 | T26: =$E26*K26 -> 1.088 | U26: =$E26*L26 -> 1.0133333 | V26: =$E26*M26 -> 90.56 | W26: =$E26*N26 -> 1.6896 | X26: =$E26*O26 -> 0.064 | Z26: =10*(AVERAGE('FAO Data A2'!J63:J66)) -> 4220 | AA26: =10*(AVERAGE('FAO Data A2'!K63:K66)) -> 711.63333 | AB26: =10*(AVERAGE('FAO Data A2'!L63:L66)) -> 91.7 | AC26: =10*(AVERAGE('FAO Data A2'!M63:M66)) -> 104.36667 | AD26: =10*(AVERAGE('FAO Data A2'!N63:N66)) -> 17 | AE26: =10*(AVERAGE('FAO Data A2'!O63:O66)) -> 15.833333 | AF26: =10*(AVERAGE('FAO Data A2'!P63:P66)) -> 1415 | AG26: =10*(AVERAGE('FAO Data A2'!Q63:Q66)) -> 26.4 | AH26: =10*(AVERAGE('FAO Data A2'!R63:R66)) -> 1
D27: Sugar | E27: 0.13 | F27: 1.55 | G27: =$F27*Z27 -> 5745.3333 | H27: =$F27*AA27 -> 1482.8333 | I27: =$F27*AB27 -> 0 | J27: =$F27*AC27 -> 0 | K27: =$F27*AD27 -> 0 | L27: =$F27*AE27 -> 13.485 | M27: =$F27*AF27 -> 38.75 | N27: =$F27*AG27 -> 0.775 | O27: =$F27*AH27 -> 0 | P27: =$E27*G27 -> 746.89333 | Q27: =$E27*H27 -> 192.76833 | R27: =$E27*I27 -> 0 | S27: =$E27*J27 -> 0 | T27: =$E27*K27 -> 0 | U27: =$E27*L27 -> 1.75305 | V27: =$E27*M27 -> 5.0375 | W27: =$E27*N27 -> 0.10075 | X27: =$E27*O27 -> 0 | Z27: =10*(AVERAGE('FAO Data A2'!J79:J82)) -> 3706.6667 | AA27: =10*(AVERAGE('FAO Data A2'!K79:K82)) -> 956.66667 | AB27: =10*(AVERAGE('FAO Data A2'!L79:L82)) -> 0 | AC27: =10*(AVERAGE('FAO Data A2'!M79:M82)) -> 0 | AD27: =10*(AVERAGE('FAO Data A2'!N79:N82)) -> 0 | AE27: =10*(AVERAGE('FAO Data A2'!O79:O82)) -> 8.7 | AF27: =10*(AVERAGE('FAO Data A2'!P79:P82)) -> 25 | AG27: =10*(AVERAGE('FAO Data A2'!Q79:Q82)) -> 0.5 | AH27: =10*(AVERAGE('FAO Data A2'!R79:R82)) -> 0
D28: Oil | E28: 0.098 | F28: 0.89 | G28: =$F28*Z28 -> 5776.1 | H28: =$F28*AA28 -> 8.366 | I28: =$F28*AB28 -> 11.23625 | J28: =$F28*AC28 -> 636.261 | K28: =$F28*AD28 -> 0 | L28: =$F28*AE28 -> 2.759 | M28: =$F28*AF28 -> 316.24667 | N28: =$F28*AG28 -> 11.926 | O28: =$F28*AH28 -> 0.712 | P28: =$E28*G28 -> 566.0578 | Q28: =$E28*H28 -> 0.819868 | R28: =$E28*I28 -> 1.1011525 | S28: =$E28*J28 -> 62.353578 | T28: =$E28*K28 -> 0 | U28: =$E28*L28 -> 0.270382 | V28: =$E28*M28 -> 30.992173 | W28: =$E28*N28 -> 1.168748 | X28: =$E28*O28 -> 0.069776 | Z28: =10*(AVERAGE('FAO Data A2'!J83:J86)) -> 6490 | AA28: =10*(AVERAGE('FAO Data A2'!K83:K86)) -> 9.4 | AB28: =10*(AVERAGE('FAO Data A2'!L83:L86)) -> 12.625 | AC28: =10*(AVERAGE('FAO Data A2'!M83:M86)) -> 714.9 | AD28: =10*(AVERAGE('FAO Data A2'!N83:N86)) -> 0 | AE28: =10*(AVERAGE('FAO Data A2'!O83:O86)) -> 3.1 | AF28: =10*(AVERAGE('FAO Data A2'!P83:P86)) -> 355.33333 | AG28: =10*(AVERAGE('FAO Data A2'!Q83:Q86)) -> 13.4 | AH28: =10*(AVERAGE('FAO Data A2'!R83:R86)) -> 0.8

Sheet Table A8
D4: Table A8
F5: Weekly Consumption in Control Households | P5: Impact of Conditional Cash Transfer: | Z5: Averages from Tab FAO Data A2 (Converted to Kgs)
D6: Food Item | E6: Elasticity | F6: Kg | G6: Calories | H6: Carbs (g) | I6: Protein (g) | J6: Fat (g) | K6: Fiber (g) | L6: Ash (g) | M6: Calcium (mg) | N6: Iron (mg) | O6: Vit C (mg) | P6: Calories | Q6: Carbs (g) | R6: Protein (g) | S6: Fat (g) | T6: Fiber (g) | U6: Ash (g) | V6: Calcium (mg) | W6: Iron (mg) | X6: Vit C (mg) | Z6: Calories | AA6: Carbs (g) | AB6: Protein (g) | AC6: Fat (g) | AD6: Fiber (g) | AE6: Ash (g) | AF6: Calcium (mg) | AG6: Iron (mg) | AH6: Vit C (mg)
D7: Staples
D8: Corn | E8: 0.019 | F8: 15.36 | G8: =$F8*Z8 -> 45427.2 | H8: =$F8*AA8 -> 9158.784 | I8: =$F8*AB8 -> 1195.008 | J8: =$F8*AC8 -> 576.768 | K8: =$F8*AD8 -> 1131.52 | L8: =$F8*AE8 -> 165.12 | M8: =$F8*AF8 -> 1459.2 | N8: =$F8*AG8 -> 455.424 | O8: =$F8*AH8 -> 652.8 | P8: =$E8*G8 -> 863.1168 | Q8: =$E8*H8 -> 174.0169 | R8: =$E8*I8 -> 22.705152 | S8: =$E8*J8 -> 10.958592 | T8: =$E8*K8 -> 21.49888 | U8: =$E8*L8 -> 3.13728 | V8: =$E8*M8 -> 27.7248 | W8: =$E8*N8 -> 8.653056 | X8: =$E8*O8 -> 12.4032 | Z8: =10*(AVERAGE('FAO Data A2'!J27:J30)) -> 2957.5 | AA8: =10*(AVERAGE('FAO Data A2'!K27:K30)) -> 596.275 | AB8: =10*(AVERAGE('FAO Data A2'!L27:L30)) -> 77.8 | AC8: =10*(AVERAGE('FAO Data A2'!M27:M30)) -> 37.55 | AD8: =10*(AVERAGE('FAO Data A2'!N27:N30)) -> 73.666667 | AE8: =10*(AVERAGE('FAO Data A2'!O27:O30)) -> 10.75 | AF8: =10*(AVERAGE('FAO Data A2'!P27:P30)) -> 95 | AG8: =10*(AVERAGE('FAO Data A2'!Q27:Q30)) -> 29.65 | AH8: =10*(AVERAGE('FAO Data A2'!R27:R30)) -> 42.5
D9: Rice | E9: 0.157 | F9: 0.55 | G9: =$F9*Z9 -> 1980 | H9: =$F9*AA9 -> 438.2675 | I9: =$F9*AB9 -> 37.90875 | J9: =$F9*AC9 -> 2.95625 | K9: =$F9*AD9 -> 3.85 | L9: =$F9*AE9 -> 3.06625 | M9: =$F9*AF9 -> 83.1875 | N9: =$F9*AG9 -> 6.36625 | O9: =$F9*AH9 -> 0 | P9: =$E9*G9 -> 310.86 | Q9: =$E9*H9 -> 68.807998 | R9: =$E9*I9 -> 5.9516738 | S9: =$E9*J9 -> 0.46413125 | T9: =$E9*K9 -> 0.60445 | U9: =$E9*L9 -> 0.48140125 | V9: =$E9*M9 -> 13.060438 | W9: =$E9*N9 -> 0.99950125 | X9: =$E9*O9 -> 0 | Z9: =10*(AVERAGE('FAO Data A2'!J35:J38)) -> 3600 | AA9: =10*(AVERAGE('FAO Data A2'!K35:K38)) -> 796.85 | AB9: =10*(AVERAGE('FAO Data A2'!L35:L38)) -> 68.925 | AC9: =10*(AVERAGE('FAO Data A2'!M35:M38)) -> 5.375 | AD9: =10*(AVERAGE('FAO Data A2'!N35:N38)) -> 7 | AE9: =10*(AVERAGE('FAO Data A2'!O35:O38)) -> 5.575 | AF9: =10*(AVERAGE('FAO Data A2'!P35:P38)) -> 151.25 | AG9: =10*(AVERAGE('FAO Data A2'!Q35:Q38)) -> 11.575 | AH9: =10*(AVERAGE('FAO Data A2'!R35:R38)) -> 0
D10: Bread | E10: 0.322 | F10: 0.26 | G10: =$F10*Z10 -> 719.55 | H10: =$F10*AA10 -> 131.287 | I10: =$F10*AB10 -> 23.803 | J10: =$F10*AC10 -> 9.2646667 | K10: =$F10*AD10 -> 7.4533333 | L10: =$F10*AE10 -> 4.914 | M10: =$F10*AF10 -> 246.35 | N10: =$F10*AG10 -> 26.806 | O10: =$F10*AH10 -> 0 | P10: =$E10*G10 -> 231.6951 | Q10: =$E10*H10 -> 42.274414 | R10: =$E10*I10 -> 7.664566 | S10: =$E10*J10 -> 2.9832227 | T10: =$E10*K10 -> 2.3999733 | U10: =$E10*L10 -> 1.582308 | V10: =$E10*M10 -> 79.3247 | W10: =$E10*N10 -> 8.631532 | X10: =$E10*O10 -> 0 | Z10: =10*(AVERAGE('FAO Data A2'!J31:J34)) -> 2767.5 | AA10: =10*(AVERAGE('FAO Data A2'!K31:K34)) -> 504.95 | AB10: =10*(AVERAGE('FAO Data A2'!L31:L34)) -> 91.55 | AC10: =10*(AVERAGE('FAO Data A2'!M31:M34)) -> 35.633333 | AD10: =10*(AVERAGE('FAO Data A2'!N31:N34)) -> 28.666667 | AE10: =10*(AVERAGE('FAO Data A2'!O31:O34)) -> 18.9 | AF10: =10*(AVERAGE('FAO Data A2'!P31:P34)) -> 947.5 | AG10: =10*(AVERAGE('FAO Data A2'!Q31:Q34)) -> 103.1 | AH10: =10*(AVERAGE('FAO Data A2'!R31:R34)) -> 0
D11: Potato | E11: 0.336 | F11: 0.51 | G11: =$F11*Z11 -> 388.875 | H11: =$F11*AA11 -> 88.67625 | I11: =$F11*AB11 -> 9.95775 | J11: =$F11*AC11 -> 1.49175 | K11: =$F11*AD11 -> 8.415 | L11: =$F11*AE11 -> 6.018 | M11: =$F11*AF11 -> 63.66075 | N11: =$F11*AG11 -> 6.987 | O11: =$F11*AH11 -> 106.83225 | P11: =$E11*G11 -> 130.662 | Q11: =$E11*H11 -> 29.79522 | R11: =$E11*I11 -> 3.345804 | S11: =$E11*J11 -> 0.501228 | T11: =$E11*K11 -> 2.82744 | U11: =$E11*L11 -> 2.022048 | V11: =$E11*M11 -> 21.390012 | W11: =$E11*N11 -> 2.347632 | X11: =$E11*O11 -> 35.895636 | Z11: =10*(AVERAGE('FAO Data A2'!J39:J42)) -> 762.5 | AA11: =10*(AVERAGE('FAO Data A2'!K39:K42)) -> 173.875 | AB11: =10*(AVERAGE('FAO Data A2'!L39:L42)) -> 19.525 | AC11: =10*(AVERAGE('FAO Data A2'!M39:M42)) -> 2.925 | AD11: =10*(AVERAGE('FAO Data A2'!N39:N42)) -> 16.5 | AE11: =10*(AVERAGE('FAO Data A2'!O39:O42)) -> 11.8 | AF11: =10*(AVERAGE('FAO Data A2'!P39:P42)) -> 124.825 | AG11: =10*(AVERAGE('FAO Data A2'!Q39:Q42)) -> 13.7 | AH11: =10*(AVERAGE('FAO Data A2'!R39:R42)) -> 209.475
D12: Protein
D13: Chicken | E13: 0.425 | F13: 0.45 | G13: =$F13*Z13 -> 721.125 | H13: =$F13*AA13 -> 0 | I13: =$F13*AB13 -> 90.61875 | J13: =$F13*AC13 -> 36.21375 | K13: =$F13*AD13 -> 0 | L13: =$F13*AE13 -> 4.39875 | M13: =$F13*AF13 -> 45.86625 | N13: =$F13*AG13 -> 10.62 | O13: =$F13*AH13 -> 1.125 | P13: =$E13*G13 -> 306.47812 | Q13: =$E13*H13 -> 0 | R13: =$E13*I13 -> 38.512969 | S13: =$E13*J13 -> 15.390844 | T13: =$E13*K13 -> 0 | U13: =$E13*L13 -> 1.8694688 | V13: =$E13*M13 -> 19.493156 | W13: =$E13*N13 -> 4.5135 | X13: =$E13*O13 -> 0.478125 | Z13: =10*(AVERAGE('FAO Data A2'!J3:J6)) -> 1602.5 | AA13: =10*(AVERAGE('FAO Data A2'!K3:K6)) -> 0 | AB13: =10*(AVERAGE('FAO Data A2'!L3:L6)) -> 201.375 | AC13: =10*(AVERAGE('FAO Data A2'!M3:M6)) -> 80.475 | AD13: =10*(AVERAGE('FAO Data A2'!N3:N6)) -> 0 | AE13: =10*(AVERAGE('FAO Data A2'!O3:O6)) -> 9.775 | AF13: =10*(AVERAGE('FAO Data A2'!P3:P6)) -> 101.925 | AG13: =10*(AVERAGE('FAO Data A2'!Q3:Q6)) -> 23.6 | AH13: =10*(AVERAGE('FAO Data A2'!R3:R6)) -> 2.5
D14: Pork | E14: 0.191 | F14: 0.2 | G14: =$F14*Z14 -> 427 | H14: =$F14*AA14 -> 0 | I14: =$F14*AB14 -> 38.3 | J14: =$F14*AC14 -> 29.785 | K14: =$F14*AD14 -> 0 | L14: =$F14*AE14 -> 2.095 | M14: =$F14*AF14 -> 12.5 | N14: =$F14*AG14 -> 2.245 | O14: =$F14*AH14 -> 0 | P14: =$E14*G14 -> 81.557 | Q14: =$E14*H14 -> 0 | R14: =$E14*I14 -> 7.3153 | S14: =$E14*J14 -> 5.688935 | T14: =$E14*K14 -> 0 | U14: =$E14*L14 -> 0.400145 | V14: =$E14*M14 -> 2.3875 | W14: =$E14*N14 -> 0.428795 | X14: =$E14*O14 -> 0 | Z14: =10*(AVERAGE('FAO Data A2'!J7:J10)) -> 2135 | AA14: =10*(AVERAGE('FAO Data A2'!K7:K10)) -> 0 | AB14: =10*(AVERAGE('FAO Data A2'!L7:L10)) -> 191.5 | AC14: =10*(AVERAGE('FAO Data A2'!M7:M10)) -> 148.925 | AD14: =10*(AVERAGE('FAO Data A2'!N7:N10)) -> 0 | AE14: =10*(AVERAGE('FAO Data A2'!O7:O10)) -> 10.475 | AF14: =10*(AVERAGE('FAO Data A2'!P7:P10)) -> 62.5 | AG14: =10*(AVERAGE('FAO Data A2'!Q7:Q10)) -> 11.225 | AH14: =10*(AVERAGE('FAO Data A2'!R7:R10)) -> 0
D15: Beef | E15: 0.23 | F15: 0.23 | G15: =$F15*Z15 -> 408.25 | H15: =$F15*AA15 -> 1.6675 | I15: =$F15*AB15 -> 42.91225 | J15: =$F15*AC15 -> 24.05225 | K15: =$F15*AD15 -> 0 | L15: =$F15*AE15 -> 3.39825 | M15: =$F15*AF15 -> 25.3 | N15: =$F15*AG15 -> 7.14725 | O15: =$F15*AH15 -> 0 | P15: =$E15*G15 -> 93.8975 | Q15: =$E15*H15 -> 0.383525 | R15: =$E15*I15 -> 9.8698175 | S15: =$E15*J15 -> 5.5320175 | T15: =$E15*K15 -> 0 | U15: =$E15*L15 -> 0.7815975 | V15: =$E15*M15 -> 5.819 | W15: =$E15*N15 -> 1.6438675 | X15: =$E15*O15 -> 0 | Z15: =10*(AVERAGE('FAO Data A2'!J59:J62)) -> 1775 | AA15: =10*(AVERAGE('FAO Data A2'!K59:K62)) -> 7.25 | AB15: =10*(AVERAGE('FAO Data A2'!L59:L62)) -> 186.575 | AC15: =10*(AVERAGE('FAO Data A2'!M59:M62)) -> 104.575 | AD15: =10*(AVERAGE('FAO Data A2'!N59:N62)) -> 0 | AE15: =10*(AVERAGE('FAO Data A2'!O59:O62)) -> 14.775 | AF15: =10*(AVERAGE('FAO Data A2'!P59:P62)) -> 110 | AG15: =10*(AVERAGE('FAO Data A2'!Q59:Q62)) -> 31.075 | AH15: =10*(AVERAGE('FAO Data A2'!R59:R62)) -> 0
D16: Fish | E16: 0.069 | F16: 0.04 | G16: =$F16*Z16 -> 40.6 | H16: =$F16*AA16 -> 0 | I16: =$F16*AB16 -> 6.771 | J16: =$F16*AC16 -> 1.252 | K16: =$F16*AD16 -> 0 | L16: =$F16*AE16 -> 0.422 | M16: =$F16*AF16 -> 12.7 | N16: =$F16*AG16 -> 0.273 | O16: =$F16*AH16 -> 0.26666667 | P16: =$E16*G16 -> 2.8014 | Q16: =$E16*H16 -> 0 | R16: =$E16*I16 -> 0.467199 | S16: =$E16*J16 -> 0.086388 | T16: =$E16*K16 -> 0 | U16: =$E16*L16 -> 0.029118 | V16: =$E16*M16 -> 0.8763 | W16: =$E16*N16 -> 0.018837 | X16: =$E16*O16 -> 0.0184 | Z16: =10*(AVERAGE('FAO Data A2'!J15:J18)) -> 1015 | AA16: =10*(AVERAGE('FAO Data A2'!K15:K18)) -> 0 | AB16: =10*(AVERAGE('FAO Data A2'!L15:L18)) -> 169.275 | AC16: =10*(AVERAGE('FAO Data A2'!M15:M18)) -> 31.3 | AD16: =10*(AVERAGE('FAO Data A2'!N15:N18)) -> 0 | AE16: =10*(AVERAGE('FAO Data A2'!O15:O18)) -> 10.55 | AF16: =10*(AVERAGE('FAO Data A2'!P15:P18)) -> 317.5 | AG16: =10*(AVERAGE('FAO Data A2'!Q15:Q18)) -> 6.825 | AH16: =10*(AVERAGE('FAO Data A2'!R15:R18)) -> 6.6666667
D17: Eggs | E17: 0.22 | F17: 0.85 | G17: =$F17*Z17 -> 1255.875 | H17: =$F17*AA17 -> 16.575 | I17: =$F17*AB17 -> 105.995 | J17: =$F17*AC17 -> 83.5975 | K17: =$F17*AD17 -> 0 | L17: =$F17*AE17 -> 8.84 | M17: =$F17*AF17 -> 425.7225 | N17: =$F17*AG17 -> 19.0825 | O17: =$F17*AH17 -> 0 | P17: =$E17*G17 -> 276.2925 | Q17: =$E17*H17 -> 3.6465 | R17: =$E17*I17 -> 23.3189 | S17: =$E17*J17 -> 18.39145 | T17: =$E17*K17 -> 0 | U17: =$E17*L17 -> 1.9448 | V17: =$E17*M17 -> 93.65895 | W17: =$E17*N17 -> 4.19815 | X17: =$E17*O17 -> 0 | Z17: =10*(AVERAGE('FAO Data A2'!J19:J22)) -> 1477.5 | AA17: =10*(AVERAGE('FAO Data A2'!K19:K22)) -> 19.5 | AB17: =10*(AVERAGE('FAO Data A2'!L19:L22)) -> 124.7 | AC17: =10*(AVERAGE('FAO Data A2'!M19:M22)) -> 98.35 | AD17: =10*(AVERAGE('FAO Data A2'!N19:N22)) -> 0 | AE17: =10*(AVERAGE('FAO Data A2'!O19:O22)) -> 10.4 | AF17: =10*(AVERAGE('FAO Data A2'!P19:P22)) -> 500.85 | AG17: =10*(AVERAGE('FAO Data A2'!Q19:Q22)) -> 22.45 | AH17: =10*(AVERAGE('FAO Data A2'!R19:R22)) -> 0
D18: Milk | E18: 0.152 | F18: 0.71 | G18: =$F18*Z18 -> 479.25 | H18: =$F18*AA18 -> 33.228 | I18: =$F18*AB18 -> 23.998 | J18: =$F18*AC18 -> 31.43525 | K18: =$F18*AD18 -> 0 | L18: =$F18*AE18 -> 5.12975 | M18: =$F18*AF18 -> 855.692 | N18: =$F18*AG18 -> 5.893 | O18: =$F18*AH18 -> 3.55 | P18: =$E18*G18 -> 72.846 | Q18: =$E18*H18 -> 5.050656 | R18: =$E18*I18 -> 3.647696 | S18: =$E18*J18 -> 4.778158 | T18: =$E18*K18 -> 0 | U18: =$E18*L18 -> 0.779722 | V18: =$E18*M18 -> 130.06518 | W18: =$E18*N18 -> 0.895736 | X18: =$E18*O18 -> 0.5396 | Z18: =10*(AVERAGE('FAO Data A2'!J23:J26)) -> 675 | AA18: =10*(AVERAGE('FAO Data A2'!K23:K26)) -> 46.8 | AB18: =10*(AVERAGE('FAO Data A2'!L23:L26)) -> 33.8 | AC18: =10*(AVERAGE('FAO Data A2'!M23:M26)) -> 44.275 | AD18: =10*(AVERAGE('FAO Data A2'!N23:N26)) -> 0 | AE18: =10*(AVERAGE('FAO Data A2'!O23:O26)) -> 7.225 | AF18: =10*(AVERAGE('FAO Data A2'!P23:P26)) -> 1205.2 | AG18: =10*(AVERAGE('FAO Data A2'!Q23:Q26)) -> 8.3 | AH18: =10*(AVERAGE('FAO Data A2'!R23:R26)) -> 5
D19: Beans | E19: 0.074 | F19: 1.87 | G19: =$F19*Z19 -> 7428.575 | H19: =$F19*AA19 -> 464.36775 | I19: =$F19*AB19 -> 684.233 | J19: =$F19*AC19 -> 346.7915 | K19: =$F19*AD19 -> 211.7775 | L19: =$F19*AE19 -> 92.752 | M19: =$F19*AF19 -> 4576.825 | N19: =$F19*AG19 -> 196.58375 | O19: =$F19*AH19 -> 79.475 | P19: =$E19*G19 -> 549.71455 | Q19: =$E19*H19 -> 34.363213 | R19: =$E19*I19 -> 50.633242 | S19: =$E19*J19 -> 25.662571 | T19: =$E19*K19 -> 15.671535 | U19: =$E19*L19 -> 6.863648 | V19: =$E19*M19 -> 338.68505 | W19: =$E19*N19 -> 14.547198 | X19: =$E19*O19 -> 5.88115 | Z19: =10*(AVERAGE('FAO Data A2'!J67:J70)) -> 3972.5 | AA19: =10*(AVERAGE('FAO Data A2'!K67:K70)) -> 248.325 | AB19: =10*(AVERAGE('FAO Data A2'!L67:L70)) -> 365.9 | AC19: =10*(AVERAGE('FAO Data A2'!M67:M70)) -> 185.45 | AD19: =10*(AVERAGE('FAO Data A2'!N67:N70)) -> 113.25 | AE19: =10*(AVERAGE('FAO Data A2'!O67:O70)) -> 49.6 | AF19: =10*(AVERAGE('FAO Data A2'!P67:P70)) -> 2447.5 | AG19: =10*(AVERAGE('FAO Data A2'!Q67:Q70)) -> 105.125 | AH19: =10*(AVERAGE('FAO Data A2'!R67:R70)) -> 42.5
D20: Vegetables & Fruits
D21: Tomato | E21: 0.168 | F21: 0.96 | G21: =$F21*Z21 -> 187.2 | H21: =$F21*AA21 -> 33.84 | I21: =$F21*AB21 -> 8.376 | J21: =$F21*AC21 -> 2.256 | K21: =$F21*AD21 -> 9.84 | L21: =$F21*AE21 -> 5.352 | M21: =$F21*AF21 -> 106.8 | N21: =$F21*AG21 -> 5.976 | O21: =$F21*AH21 -> 229.272 | P21: =$E21*G21 -> 31.4496 | Q21: =$E21*H21 -> 5.68512 | R21: =$E21*I21 -> 1.407168 | S21: =$E21*J21 -> 0.379008 | T21: =$E21*K21 -> 1.65312 | U21: =$E21*L21 -> 0.899136 | V21: =$E21*M21 -> 17.9424 | W21: =$E21*N21 -> 1.003968 | X21: =$E21*O21 -> 38.517696 | Z21: =10*(AVERAGE('FAO Data A2'!J43:J46)) -> 195 | AA21: =10*(AVERAGE('FAO Data A2'!K43:K46)) -> 35.25 | AB21: =10*(AVERAGE('FAO Data A2'!L43:L46)) -> 8.725 | AC21: =10*(AVERAGE('FAO Data A2'!M43:M46)) -> 2.35 | AD21: =10*(AVERAGE('FAO Data A2'!N43:N46)) -> 10.25 | AE21: =10*(AVERAGE('FAO Data A2'!O43:O46)) -> 5.575 | AF21: =10*(AVERAGE('FAO Data A2'!P43:P46)) -> 111.25 | AG21: =10*(AVERAGE('FAO Data A2'!Q43:Q46)) -> 6.225 | AH21: =10*(AVERAGE('FAO Data A2'!R43:R46)) -> 238.825
D22: Leafy Greens | E22: 0.056 | F22: 0.07 | G22: =$F22*Z22 -> 18.9875 | H22: =$F22*AA22 -> 2.338 | I22: =$F22*AB22 -> 2.0615 | J22: =$F22*AC22 -> 0.21525 | K22: =$F22*AD22 -> 1.519 | L22: =$F22*AE22 -> 1.3125 | M22: =$F22*AF22 -> 131.83275 | N22: =$F22*AG22 -> 2.4885 | O22: =$F22*AH22 -> 30.66 | P22: =$E22*G22 -> 1.0633 | Q22: =$E22*H22 -> 0.130928 | R22: =$E22*I22 -> 0.115444 | S22: =$E22*J22 -> 0.012054 | T22: =$E22*K22 -> 0.085064 | U22: =$E22*L22 -> 0.0735 | V22: =$E22*M22 -> 7.382634 | W22: =$E22*N22 -> 0.139356 | X22: =$E22*O22 -> 1.71696 | Z22: =10*(AVERAGE('FAO Data A2'!J87:J90)) -> 271.25 | AA22: =10*(AVERAGE('FAO Data A2'!K87:K90)) -> 33.4 | AB22: =10*(AVERAGE('FAO Data A2'!L87:L90)) -> 29.45 | AC22: =10*(AVERAGE('FAO Data A2'!M87:M90)) -> 3.075 | AD22: =10*(AVERAGE('FAO Data A2'!N87:N90)) -> 21.7 | AE22: =10*(AVERAGE('FAO Data A2'!O87:O90)) -> 18.75 | AF22: =10*(AVERAGE('FAO Data A2'!P87:P90)) -> 1883.325 | AG22: =10*(AVERAGE('FAO Data A2'!Q87:Q90)) -> 35.55 | AH22: =10*(AVERAGE('FAO Data A2'!R87:R90)) -> 438
D23: Onion | E23: 0.144 | F23: 0.64 | G23: =$F23*Z23 -> 230.4 | H23: =$F23*AA23 -> 46.208 | I23: =$F23*AB23 -> 11.296 | J23: =$F23*AC23 -> 1.792 | K23: =$F23*AD23 -> 14.08 | L23: =$F23*AE23 -> 4.672 | M23: =$F23*AF23 -> 361.6 | N23: =$F23*AG23 -> 9.696 | O23: =$F23*AH23 -> 142.4 | P23: =$E23*G23 -> 33.1776 | Q23: =$E23*H23 -> 6.653952 | R23: =$E23*I23 -> 1.626624 | S23: =$E23*J23 -> 0.258048 | T23: =$E23*K23 -> 2.02752 | U23: =$E23*L23 -> 0.672768 | V23: =$E23*M23 -> 52.0704 | W23: =$E23*N23 -> 1.396224 | X23: =$E23*O23 -> 20.5056 | Z23: =10*(AVERAGE('FAO Data A2'!J55:J58)) -> 360 | AA23: =10*(AVERAGE('FAO Data A2'!K55:K58)) -> 72.2 | AB23: =10*(AVERAGE('FAO Data A2'!L55:L58)) -> 17.65 | AC23: =10*(AVERAGE('FAO Data A2'!M55:M58)) -> 2.8 | AD23: =10*(AVERAGE('FAO Data A2'!N55:N58)) -> 22 | AE23: =10*(AVERAGE('FAO Data A2'!O55:O58)) -> 7.3 | AF23: =10*(AVERAGE('FAO Data A2'!P55:P58)) -> 565 | AG23: =10*(AVERAGE('FAO Data A2'!Q55:Q58)) -> 15.15 | AH23: =10*(AVERAGE('FAO Data A2'!R55:R58)) -> 222.5
D24: Banana | E24: 0.252 | F24: 0.53 | G24: =$F24*Z24 -> 477 | H24: =$F24*AA24 -> 114.1885 | I24: =$F24*AB24 -> 6.5985 | J24: =$F24*AC24 -> 1.643 | K24: =$F24*AD24 -> 9.54 | L24: =$F24*AE24 -> 4.399 | M24: =$F24*AF24 -> 42.4 | N24: =$F24*AG24 -> 3.074 | O24: =$F24*AH24 -> 476.6025 | P24: =$E24*G24 -> 120.204 | Q24: =$E24*H24 -> 28.775502 | R24: =$E24*I24 -> 1.662822 | S24: =$E24*J24 -> 0.414036 | T24: =$E24*K24 -> 2.40408 | U24: =$E24*L24 -> 1.108548 | V24: =$E24*M24 -> 10.6848 | W24: =$E24*N24 -> 0.774648 | X24: =$E24*O24 -> 120.10383 | Z24: =10*(AVERAGE('FAO Data A2'!J51:J54)) -> 900 | AA24: =10*(AVERAGE('FAO Data A2'!K51:K54)) -> 215.45 | AB24: =10*(AVERAGE('FAO Data A2'!L51:L54)) -> 12.45 | AC24: =10*(AVERAGE('FAO Data A2'!M51:M54)) -> 3.1 | AD24: =10*(AVERAGE('FAO Data A2'!N51:N54)) -> 18 | AE24: =10*(AVERAGE('FAO Data A2'!O51:O54)) -> 8.3 | AF24: =10*(AVERAGE('FAO Data A2'!P51:P54)) -> 80 | AG24: =10*(AVERAGE('FAO Data A2'!Q51:Q54)) -> 5.8 | AH24: =10*(AVERAGE('FAO Data A2'!R51:R54)) -> 899.25
D25: Other
D26: Cookies | E26: 0.064 | F26: 0.07 | G26: =$F26*Z26 -> 295.4 | H26: =$F26*AA26 -> 49.814333 | I26: =$F26*AB26 -> 6.419 | J26: =$F26*AC26 -> 7.3056667 | K26: =$F26*AD26 -> 1.19 | L26: =$F26*AE26 -> 1.1083333 | M26: =$F26*AF26 -> 99.05 | N26: =$F26*AG26 -> 1.848 | O26: =$F26*AH26 -> 0.07 | P26: =$E26*G26 -> 18.9056 | Q26: =$E26*H26 -> 3.1881173 | R26: =$E26*I26 -> 0.410816 | S26: =$E26*J26 -> 0.46756267 | T26: =$E26*K26 -> 0.07616 | U26: =$E26*L26 -> 0.070933333 | V26: =$E26*M26 -> 6.3392 | W26: =$E26*N26 -> 0.118272 | X26: =$E26*O26 -> 0.00448 | Z26: =10*(AVERAGE('FAO Data A2'!J63:J66)) -> 4220 | AA26: =10*(AVERAGE('FAO Data A2'!K63:K66)) -> 711.63333 | AB26: =10*(AVERAGE('FAO Data A2'!L63:L66)) -> 91.7 | AC26: =10*(AVERAGE('FAO Data A2'!M63:M66)) -> 104.36667 | AD26: =10*(AVERAGE('FAO Data A2'!N63:N66)) -> 17 | AE26: =10*(AVERAGE('FAO Data A2'!O63:O66)) -> 15.833333 | AF26: =10*(AVERAGE('FAO Data A2'!P63:P66)) -> 1415 | AG26: =10*(AVERAGE('FAO Data A2'!Q63:Q66)) -> 26.4 | AH26: =10*(AVERAGE('FAO Data A2'!R63:R66)) -> 1
D27: Sugar | E27: 0.13 | F27: 1.55 | G27: =$F27*Z27 -> 5745.3333 | H27: =$F27*AA27 -> 1482.8333 | I27: =$F27*AB27 -> 0 | J27: =$F27*AC27 -> 0 | K27: =$F27*AD27 -> 0 | L27: =$F27*AE27 -> 13.485 | M27: =$F27*AF27 -> 38.75 | N27: =$F27*AG27 -> 0.775 | O27: =$F27*AH27 -> 0 | P27: =$E27*G27 -> 746.89333 | Q27: =$E27*H27 -> 192.76833 | R27: =$E27*I27 -> 0 | S27: =$E27*J27 -> 0 | T27: =$E27*K27 -> 0 | U27: =$E27*L27 -> 1.75305 | V27: =$E27*M27 -> 5.0375 | W27: =$E27*N27 -> 0.10075 | X27: =$E27*O27 -> 0 | Z27: =10*(AVERAGE('FAO Data A2'!J79:J82)) -> 3706.6667 | AA27: =10*(AVERAGE('FAO Data A2'!K79:K82)) -> 956.66667 | AB27: =10*(AVERAGE('FAO Data A2'!L79:L82)) -> 0 | AC27: =10*(AVERAGE('FAO Data A2'!M79:M82)) -> 0 | AD27: =10*(AVERAGE('FAO Data A2'!N79:N82)) -> 0 | AE27: =10*(AVERAGE('FAO Data A2'!O79:O82)) -> 8.7 | AF27: =10*(AVERAGE('FAO Data A2'!P79:P82)) -> 25 | AG27: =10*(AVERAGE('FAO Data A2'!Q79:Q82)) -> 0.5 | AH27: =10*(AVERAGE('FAO Data A2'!R79:R82)) -> 0
D28: Oil | E28: 0.098 | F28: 0.88 | G28: =$F28*Z28 -> 5711.2 | H28: =$F28*AA28 -> 8.272 | I28: =$F28*AB28 -> 11.11 | J28: =$F28*AC28 -> 629.112 | K28: =$F28*AD28 -> 0 | L28: =$F28*AE28 -> 2.728 | M28: =$F28*AF28 -> 312.69333 | N28: =$F28*AG28 -> 11.792 | O28: =$F28*AH28 -> 0.704 | P28: =$E28*G28 -> 559.6976 | Q28: =$E28*H28 -> 0.810656 | R28: =$E28*I28 -> 1.08878 | S28: =$E28*J28 -> 61.652976 | T28: =$E28*K28 -> 0 | U28: =$E28*L28 -> 0.267344 | V28: =$E28*M28 -> 30.643947 | W28: =$E28*N28 -> 1.155616 | X28: =$E28*O28 -> 0.068992 | Z28: =10*(AVERAGE('FAO Data A2'!J83:J86)) -> 6490 | AA28: =10*(AVERAGE('FAO Data A2'!K83:K86)) -> 9.4 | AB28: =10*(AVERAGE('FAO Data A2'!L83:L86)) -> 12.625 | AC28: =10*(AVERAGE('FAO Data A2'!M83:M86)) -> 714.9 | AD28: =10*(AVERAGE('FAO Data A2'!N83:N86)) -> 0 | AE28: =10*(AVERAGE('FAO Data A2'!O83:O86)) -> 3.1 | AF28: =10*(AVERAGE('FAO Data A2'!P83:P86)) -> 355.33333 | AG28: =10*(AVERAGE('FAO Data A2'!Q83:Q86)) -> 13.4 | AH28: =10*(AVERAGE('FAO Data A2'!R83:R86)) -> 0.8

Sheet FAO Data A1
C2: Study | D2: Table A1 Category | E2: INFOODs database Categories | F2: Food | G2: source | H2: ID | I2: description | J2: Unit | K2: Kcal | L2: Carbs(g) | M2: Protein (g) | N2: Fat (g) | O2: Fiber (g) | P2: Ash (g) | Q2: Calcium (mg) | R2: Iron (mg) | S2: Vit C (mg)
C3: Pal | D3: Vegetables & Fruits | E3: Fruit and their products | F3: apple | G3: Tables of Composition of Food and Food Products | I3: Apple | J3: per 100g edible portion | K3: 52 | L3: 12.98 | M3: 0.32 | N3: 0.09 | O3: 2.4 | P3: 0.37 | Q3: 6.17 | R3: 0.41 | S3: 0
C4: progresa | D4: Vegetables & Fruits | E4: Fruit and their products | F4: apple | G4: Tables of Composition of Food and Food Products | I4: Apple | J4: per 100g edible portion | K4: 52 | L4: 12.98 | M4: 0.32 | N4: 0.09 | O4: 2.4 | P4: 0.37 | Q4: 6.17 | R4: 0.41 | S4: 0
C5: Uganda | D5: Vegetables & Fruits | E5: Fruit and their products | F5: avocado | G5: Food Composition Table for Use in Africa | H5: 863 | I5: Avocado, American: alligator pear, raw | J5: per 100g edible portion | K5: 121 | L5: 6.1 | M5: 1.4 | N5: 11.3 | O5: 1.8 | P5: 0.9 | Q5: 19 | R5: 1.4 | S5: 18
C6: Nicaragua | D6: Vegetables & Fruits | E6: Fruit and their products | F6: avocado | G6: Tabla de Composicion de Alimentos de Centroamerica | H6: 11005 | I6: Avocado, raw | J6: per 100g edible portion | K6: 160 | L6: 8.53 | M6: 2 | N6: 14.66 | O6: 6.7 | P6: 1.58 | Q6: 12 | R6: 0.55 | S6: 10
C7: Uganda | D7: Vegetables & Fruits | E7: Fruit and their products | F7: banana | G7: Food Composition Table for Use in Africa | H7: 199 | I7: banana, common, ripe | J7: per 100g edible portion | K7: 88 | L7: 20.6 | M7: 1.5 | N7: 0.1 | O7: 0.9 | P7: 0.8 | Q7: 9 | R7: 1.4 | S7: 9
C8: Pal | D8: Vegetables & Fruits | E8: Fruit and their products | F8: banana | G8: Tables of Composition of Food and Food Products | I8: banana | J8: per 100g edible portion | K8: 89 | L8: 22.84 | M8: 1.09 | N8: 0.21 | O8: 2 | P8: 0.9 | Q8: 5 | R8: 0.26 | S8: 333.7
C9: progresa | D9: Vegetables & Fruits | E9: Fruit and their products | F9: banana | G9: Tables of Composition of Food and Food Products | I9: banana | J9: per 100g edible portion | K9: 89 | L9: 22.84 | M9: 1.09 | N9: 0.21 | O9: 2 | P9: 0.9 | Q9: 5 | R9: 0.26 | S9: 333.7
C10: Nicaragua | D10: Vegetables & Fruits | E10: Fruit and their products | F10: banana | G10: Tabla de Composicion de Alimentos de Centroamerica | H10: 12010 | I10: banana, maute raw | J10: per 100g edible portion | K10: 89 | L10: 22.84 | M10: 1.09 | N10: 0.33 | O10: 2.6 | P10: 0.82 | Q10: 5 | R10: 0.26 | S10: 9
C11: Pal | D11: Protein | E11: Meat | F11: beef | G11: Tables of Composition of Food and Food Products | I11: Bovines, beef | J11: per 100g edible portion | K11: 155 | L11: 0 | M11: 21.25 | N11: 6.28 | O11: 0 | P11: 1.6 | Q11: 5 | R11: 1.92 | S11: 0
C12: Progresa | D12: Protein | E12: Meat | F12: beef | G12: Tables of Composition of Food and Food Products | I12: Bovines, beef | J12: per 100g edible portion | K12: 155 | L12: 0 | M12: 21.25 | N12: 6.28 | O12: 0 | P12: 1.6 | Q12: 5 | R12: 1.92 | S12: 0
C13: Nicaragua | D13: Protein | E13: Meat | F13: beef | G13: Tabla de Composicion de Alimentos de Centroamerica | H13: 5022 | I13: Beef, full cut, lean&fat 1/8" Raw | J13: per 100g edible portion | K13: 234 | L13: 0 | M13: 18.68 | N13: 17.15 | O13: 0 | P13: 0.91 | Q13: 7 | R13: 1.91 | S13: 0
C14: Philippines | D14: Protein | E14: Meat | F14: beef | G14: ASEAN Food Composition Database | H14: AAF2 | I14: Beef, meat ball | J14: per 100g edible portion | K14: 84 | L14: 2.9 | M14: 16.5 | N14: 0.7 | O14: 0 | P14: 2.4 | Q14: 21 | R14: 5
C15: Uganda | D15: Protein | E15: Meat | F15: beef | G15: Food Composition Table for Use in Africa | H15: 1080 | I15: Beef, zebu, medium fat | J15: per 100g edible portion | K15: 237 | L15: 0 | M15: 18.2 | N15: 17.7 | O15: 0 | P15: 1 | Q15: 11 | R15: 3.6
C16: Philippines | D16: Staples (coarse & fine) | E16: Cereals | F16: biscuits | G16: ASEAN Food Composition Database | J16: per 100g edible portion
C17: Uganda | D17: Protein | F17: blood | G17: Food Composition Table for Use in Africa | J17: per 100g edible portion
C18: Nicaragua | D18: Protein | F18: bones | G18: Tabla de Composicion de Alimentos de Centroamerica | J18: per 100g edible portion
C19: Pal | D19: Staples (coarse & fine) | E19: Cereals | F19: box bread | G19: Tables of Composition of Food and Food Products | J19: per 100g edible portion
C20: Progresa | D20: Staples (coarse & fine) | E20: Cereals | F20: box bread | G20: Tables of Composition of Food and Food Products | J20: per 100g edible portion
C21: Nicaragua | D21: Staples (coarse & fine) | E21: Cereals | F21: bread | G21: Tabla de Composicion de Alimentos de Centroamerica | H21: 14021 | J21: per 100g edible portion | K21: 266 | L21: 50.61 | M21: 7.64 | N21: 3.29 | O21: 2.4 | P21: 2.03 | Q21: 151 | R21: 3.74 | S21: 0
C22: Philippines | D22: Staples (coarse & fine) | E22: Cereals | F22: bread | G22: ASEAN Food Composition Database | H22: AAA19 | J22: per 100g edible portion | K22: 273 | L22: 41.3 | M22: 11.9 | N22: 5.4 | O22: 5.9 | P22: 2 | Q22: 83 | R22: 1.9
C23: Uganda | D23: Staples (coarse & fine) | E23: Cereals | F23: bread | G23: Food Composition Table for Use in Africa | H23: 26 | I23: White Bread | J23: per 100g edible portion | K23: 261 | L23: 51.7 | M23: 7.7 | N23: 2 | O23: 0.3 | P23: 1.7 | Q23: 37 | R23: 1.7 | S23: 0
C24: Pal | D24: Vegetables & Fruits | E24: Vegetables and their Products | F24: cactus | G24: Tables of Composition of Food and Food Products | I24: Cactus | J24: per 100g edible portion | K24: 24 | L24: 5.1 | M24: 1.45 | N24: 0.09 | O24: 2.2 | P24: 1.2 | Q24: 93 | R24: 2.34 | S24: 15.1
C25: progresa | D25: Vegetables & Fruits | E25: Vegetables and their Products | F25: cactus | G25: Tables of Composition of Food and Food Products | I25: Cactus | J25: per 100g edible portion | K25: 24 | L25: 5.1 | M25: 1.45 | N25: 0.09 | O25: 2.2 | P25: 1.2 | Q25: 93 | R25: 2.34 | S25: 15.1
C26: Pal | D26: Vegetables & Fruits | E26: Vegetables and their Products | F26: carrot | G26: Tables of Composition of Food and Food Products | I26: Carrot | J26: per 100g edible portion | K26: 51 | L26: 12.34 | M26: 0.44 | N26: 0.17 | O26: 2.8 | P26: 0.75 | Q26: 26.5 | R26: 1.47 | S26: 15
C27: progresa | D27: Vegetables & Fruits | E27: Vegetables and their Products | F27: carrot | G27: Tables of Composition of Food and Food Products | I27: Carrot | J27: per 100g edible portion | K27: 51 | L27: 12.34 | M27: 0.44 | N27: 0.17 | O27: 2.8 | P27: 0.75 | Q27: 26.5 | R27: 1.47 | S27: 15
C28: Nicaragua | D28: Vegetables & Fruits | E28: Vegetables and their Products | F28: carrot | G28: Tabla de Composicion de Alimentos de Centroamerica | H28: 11169 | I28: Carrots, w/skin, raw | J28: per 100g edible portion | K28: 41 | L28: 9.58 | M28: 0.93 | N28: 0.24 | O28: 2.8 | P28: 0.97 | Q28: 33 | R28: 0.3 | S28: 6
C29: Philippines | D29: Tubers | E29: Roots, Tubers, Plantains | F29: cassava | G29: ASEAN Food Composition Database | H29: AAB6 | I29: Cassava, tuber, fresh, raw | J29: per 100g edible portion | K29: 146 | L29: 34.5 | M29: 0.8 | N29: 0.2 | O29: 1.7 | P29: 0.9 | Q29: 32 | R29: 1 | S29: 45
C30: Uganda | D30: Tubers | E30: Roots, Tubers, Plantains | F30: cassava | G30: Food Composition Table for Use in Africa | H30: 213 | I30: (Canna bidentata), tuber, edible Cassava, common, bitter, raw | J30: per 100g edible portion | K30: 149 | L30: 35.7 | M30: 1.2 | N30: 0.2 | O30: 1.1 | P30: 0.9 | Q30: 68 | R30: 1.9 | S30: 31
C31: Pal | D31: Vegetables & Fruits | E31: Fruit and their products | F31: chayote | G31: Tables of Composition of Food and Food Products | I31: Chayote | J31: per 100g edible portion | K31: 19 | L31: 4.51 | M31: 0.82 | N31: 0.1 | O31: 1.7 | P31: 0.3 | Q31: 17 | R31: 0.34 | S31: 7.7
C32: Pal | D32: Protein | E32: Meat | F32: chicken | G32: Tables of Composition of Food and Food Products | I32: Poultry, Chicken breast with skin | J32: per 100g edible portion | K32: 171 | L32: 0 | M32: 19.3 | N32: 8.44 | O32: 0 | P32: 0.9 | Q32: 7.77 | R32: 6.7 | S32: 0
C33: Progresa | D33: Protein | E33: Meat | F33: chicken | G33: Tables of Composition of Food and Food Products | I33: Poultry, Chicken breast with skin | J33: per 100g edible portion | K33: 171 | L33: 0 | M33: 19.3 | N33: 8.44 | O33: 0 | P33: 0.9 | Q33: 7.77 | R33: 6.7 | S33: 0
C34: Nicaragua | D34: Protein | E34: Meat | F34: chicken | G34: Tabla de Composicion de Alimentos de Centroamerica | H34: 3038 | I34: Chicken, Breast Meat & Skin, Raw | J34: per 100g edible portion | K34: 172 | L34: 0 | M34: 20.85 | N34: 9.25 | O34: 0 | P34: 1.01 | Q34: 11 | R34: 0.74 | S34: 0
C35: Philippines | D35: Protein | E35: Meat | F35: chicken | G35: ASEAN Food Composition Database | H35: AAF99 | I35: breast, w/ skin, raw | J35: per 100g edible portion | K35: 152 | L35: 0 | M35: 19.9 | N35: 8 | O35: 0 | P35: 1 | Q35: 12 | R35: 0.9 | S35: 1
C36: Nicaragua | D36: Vegetables & Fruits | F36: citrus fruits | G36: Tabla de Composicion de Alimentos de Centroamerica | J36: per 100g edible portion
C37: Philippines | D37: Vegetables & Fruits | E37: Fruit and their products | F37: coconut | G37: ASEAN Food Composition Database | H37: AAK6 | I37: Coconut, mature kernel | J37: per 100g edible portion | K37: 362 | L37: 2.7 | M37: 5.2 | N37: 35.3 | O37: 6.5 | P37: 1 | Q37: 24 | R37: 10.7 | S37: 2
C38: Pal | D38: Staples (coarse & fine) | E38: Cereals | F38: corn | G38: Tables of Composition of Food and Food Products | I38: corn, yellow grain | J38: per 100g edible portion | K38: 343 | L38: 69.55 | M38: 8.3 | N38: 4.08 | O38: 12.8 | P38: 1.2 | Q38: 8 | R38: 2.55 | S38: 0
C39: Progresa | D39: Staples (coarse & fine) | E39: Cereals | F39: corn | G39: Tables of Composition of Food and Food Products | I39: corn, yellow grain | J39: per 100g edible portion | K39: 343 | L39: 69.55 | M39: 8.3 | N39: 4.08 | O39: 12.8 | P39: 1.2 | Q39: 8 | R39: 2.55 | S39: 0
C40: Nicaragua | D40: Staples (coarse & fine) | E40: Cereals | F40: corn | G40: Tabla de Composicion de Alimentos de Centroamerica | H40: 11075 | I40: sweet corn on the co, yellow raw | J40: per 100g edible portion | K40: 86 | L40: 19.02 | M40: 3.22 | N40: 1.18 | O40: 2.7 | P40: 0.62 | Q40: 2 | R40: 0.52 | S40: 7
C41: Philippines | D41: Staples (coarse & fine) | E41: Cereals | F41: corn | G41: ASEAN Food Composition Database | H41: AAA38 | I41: Corn, whole-kernel raw | J41: per 100g edible portion | K41: 111 | L41: 21.1 | M41: 3.4 | N41: 1.4 | P41: 0.7 | Q41: 10 | R41: 1.7 | S41: 13
...

Sheet FAO Data A2
A2: Study | B2: Area | C2: Food | D2: Table A1 Category | E2: INFOODs database Categories | F2: ID | G2: Source | H2: Description | I2: Unit | J2: Kcal | K2: Carbs(g) | L2: Protein (g) | M2: Fat (g) | N2: Fiber (g) | O2: Ash (g) | P2: Calcium (mg) | Q2: Iron (mg) | R2: Vit C (mg)
A3: Pal/Progresa | B3: Mexico | C3: chicken | D3: Protein | E3: Meat | F3: Tables of Composition of Food and Food Products | H3: Poultry, Chicken breast with skin | I3: per 100g edible portion | J3: 171 | K3: 0 | L3: 19.3 | M3: 8.44 | N3: 0 | O3: 0.9 | P3: 7.77 | Q3: 6.7 | R3: 0
A4: Nicaragua | B4: Central America | C4: chicken | D4: Protein | E4: Meat | F4: 3038 | G4: Tabla de Composicion de Alimentos de Centroamerica | H4: Chicken, Breast Meat & Skin, Raw | I4: per 100g edible portion | J4: 172 | K4: 0 | L4: 20.85 | M4: 9.25 | N4: 0 | O4: 1.01 | P4: 11 | Q4: 0.74 | R4: 0 | AA4: =V4/1000 -> 0 | AB4: =W4/1000 -> 0 | AC4: =X4/1000 -> 0
A5: Philippines | B5: ASEAN | C5: chicken | D5: Protein | E5: Meat | F5: AAF99 | G5: ASEAN Food Composition Database | H5: breast, w/ skin, raw | I5: per 100g edible portion | J5: 152 | K5: 0 | L5: 19.9 | M5: 8 | N5: 0 | O5: 1 | P5: 12 | Q5: 0.9 | R5: 1 | AA5: =V5/1000 -> 0 | AB5: =W5/1000 -> 0 | AC5: =X5/1000 -> 0
A6: Uganda | B6: East Africa | C6: chicken | D6: Protein | E6: Meat | F6: 1101 | G6: Food Composition Table for Use in Africa | H6: Young bird | I6: per 100g edible portion | J6: 146 | K6: 0 | L6: 20.5 | M6: 6.5 | N6: 0 | O6: 1 | P6: 10 | Q6: 1.1 | R6: 0
A7: Pal/Progresa | B7: Mexico | C7: pork | D7: Protein | E7: Meat | F7: Tables of Composition of Food and Food Products | H7: Pork, lion | I7: per 100g edible portion | J7: 109 | K7: 0 | L7: 22.5 | M7: 1.86 | N7: 0 | O7: 1 | P7: 5 | Q7: 0.98 | R7: 0
A8: Nicaragua | B8: Central America | C8: pork | D8: Protein | E8: Meat | F8: 4003 | G8: Tabla de Composicion de Alimentos de Centroamerica | H8: Pork, Fresh, Lean&Fat, Raw | I8: per 100g edible portion | J8: 211 | K8: 0 | L8: 19.9 | M8: 14.01 | N8: 0 | O8: 0.89 | P8: 5 | Q8: 0.71 | R8: 0 | AA8: =V8/1000 -> 0 | AB8: =W8/1000 -> 0 | AC8: =X8/1000 -> 0
A9: Philippines | B9: ASEAN | C9: pork | D9: Protein | E9: Meat | F9: AAF204 | G9: ASEAN Food Composition Database | H9: Pork, tenderloin, raw | I9: per 100g edible portion | J9: 116 | K9: 0 | L9: 21.8 | M9: 3.2 | N9: 0 | O9: 1.3 | P9: 4 | Q9: 1 | R9: 0 | AA9: =V9/1000 -> 0 | AB9: =W9/1000 -> 0 | AC9: =X9/1000 -> 0
A10: Uganda | B10: East Africa | C10: pork | D10: Protein | E10: Meat | F10: 1172 | G10: Food Composition Table for Use in Africa | H10: Pork: Medium Fat | I10: per 100g edible portion | J10: 418 | K10: 0 | L10: 12.4 | M10: 40.5 | N10: 0 | O10: 1 | P10: 11 | Q10: 1.8
A11: Pal/Progresa | B11: Mexico | C11: sheepgoat | D11: Protein | E11: Meat | F11: Tables of Composition of Food and Food Products | H11: goat, leg | I11: per 100g edible portion | J11: 219 | K11: 0 | L11: 29.1 | M11: 1.91 | N11: 0 | O11: 1.8 | P11: 13 | Q11: 2.83 | R11: 0
A12: Nicaragua | B12: Central America | C12: sheepgoat | D12: Protein | E12: Meat | F12: 5001 | G12: Tabla de Composicion de Alimentos de Centroamerica | H12: goat meat, raw | I12: per 100g edible portion | J12: 109 | K12: 0 | L12: 20.6 | M12: 2.31 | N12: 0 | O12: 1.11 | P12: 13 | Q12: 2.83 | R12: 0 | AA12: =V12/1000 -> 0 | AB12: =W12/1000 -> 0 | AC12: =X12/1000 -> 0
A13: Philippines | B13: ASEAN | C13: sheepgoat | D13: Protein | E13: Meat | G13: ASEAN Food Composition Database | I13: per 100g edible portion | AA13: =V13/1000 -> 0 | AB13: =W13/1000 -> 0 | AC13: =X13/1000 -> 0
A14: Uganda | B14: East Africa | C14: sheepgoat | D14: Protein | E14: Meat | G14: Food Composition Table for Use in Africa | I14: per 100g edible portion
A15: Pal/Progresa | B15: Mexico | C15: fish | D15: Protein | E15: Fish and Shelfish | F15: Tables of Composition of Food and Food Products | H15: Catfish, raw | I15: per 100g edible portion | J15: 119 | K15: 0 | L15: 15.23 | M15: 5 | N15: 0 | O15: 0.96 | P15: 8 | Q15: 0.23 | R15: 0
A16: Nicaragua | B16: Central America | C16: fish | D16: Protein | E16: Fish and Shelfish | F16: 8023 | G16: Tabla de Composicion de Alimentos de Centroamerica | H16: Catfish, raw | I16: per 100g edible portion | J16: 95 | K16: 0 | L16: 16.38 | M16: 2.82 | N16: 0 | O16: 0.96 | P16: 14 | Q16: 0.3 | R16: 1 | AA16: =V16/1000 -> 0 | AB16: =W16/1000 -> 0 | AC16: =X16/1000 -> 0
A17: Philippines | B17: ASEAN | C17: fish | D17: Protein | E17: Fish and Shelfish | F17: AAG22 | G17: ASEAN Food Composition Database | H17: Catfish, raw | I17: per 100g edible portion | J17: 102 | K17: 0 | L17: 18.5 | M17: 3.1 | N17: 0 | O17: 1.1 | P17: 44 | Q17: 1 | R17: 1 | AA17: =V17/1000 -> 0 | AB17: =W17/1000 -> 0 | AC17: =X17/1000 -> 0
A18: Uganda | B18: East Africa | C18: fish | D18: Protein | E18: Fish and Shelfish | F18: 1255 | G18: Food Composition Table for Use in Africa | H18: Catfish, raw | I18: per 100g edible portion | J18: 90 | K18: 0 | L18: 17.6 | M18: 1.6 | N18: 0 | O18: 1.2 | P18: 61 | Q18: 1.2
A19: Pal/Progresa | B19: Mexico | C19: egg | D19: Protein | E19: Eggs | F19: Tables of Composition of Food and Food Products | H19: Egg, hen raw, whole, white | I19: per 100g edible portion | J19: 145 | K19: 4.93 | L19: 12.3 | M19: 8.7 | N19: 0 | O19: 1 | P19: 46.34 | Q19: 1.75 | R19: 0
A20: Nicaragua | B20: Central America | C20: egg | D20: Protein | E20: Eggs | F20: 2002 | G20: Tabla de Composicion de Alimentos de Centroamerica | H20: Egg, whole raw, fresh | I20: per 100g edible portion | J20: 147 | K20: 0.77 | L20: 12.58 | M20: 9.94 | N20: 0 | O20: 0.86 | P20: 53 | Q20: 1.83 | R20: 0 | AA20: =V20/1000 -> 0 | AB20: =W20/1000 -> 0 | AC20: =X20/1000 -> 0
A21: Philippines | B21: ASEAN | C21: egg | D21: Protein | E21: Eggs | F21: AAH12 | G21: ASEAN Food Composition Database | H21: egg hen whole | I21: per 100g edible portion | J21: 159 | K21: 1.5 | L21: 13.2 | M21: 11.1 | N21: 0 | O21: 1.3 | P21: 56 | Q21: 2.8 | R21: 0 | AA21: =V21/1000 -> 0 | AB21: =W21/1000 -> 0 | AC21: =X21/1000 -> 0
A22: Uganda | B22: East Africa | C22: egg | D22: Protein | E22: Eggs | F22: 1208 | G22: Food Composition Table for Use in Africa | H22: hen egg: raw | I22: per 100g edible portion | J22: 140 | K22: 0.6 | L22: 11.8 | M22: 9.6 | N22: 0 | O22: 1 | P22: 45 | Q22: 2.6
A23: Pal/Progresa | B23: Mexico | C23: milk | D23: Protein | E23: Milk and Milk Products | F23: Tables of Composition of Food and Food Products | H23: milk, cow's whole | I23: per 100g edible portion | J23: 63 | K23: 4.6 | L23: 3 | M23: 5.56 | N23: 0 | O23: 0.6 | P23: 104.08 | Q23: 2.99 | R23: 0
A24: Nicaragua | B24: Central America | C24: milk | D24: Protein | E24: Milk and Milk Products | F24: 1015 | G24: Tabla de Composicion de Alimentos de Centroamerica | H24: whole milk | I24: per 100g edible portion | J24: 60 | K24: 4.52 | L24: 3.22 | M24: 3.25 | N24: 0 | O24: 0.69 | P24: 113 | Q24: 0.03 | R24: 0 | AA24: =V24/1000 -> 0 | AB24: =W24/1000 -> 0 | AC24: =X24/1000 -> 0
A25: Philippines | B25: ASEAN | C25: milk | D25: Protein | E25: Milk and Milk Products | F25: AAJ12 | G25: ASEAN Food Composition Database | I25: per 100g edible portion | J25: 68 | K25: 4.2 | L25: 3.5 | M25: 4.1 | N25: 0 | O25: 0.8 | P25: 122 | Q25: 0.3 | R25: 1 | AA25: =V25/1000 -> 0 | AB25: =W25/1000 -> 0 | AC25: =X25/1000 -> 0
A26: Uganda | B26: East Africa | C26: milk | D26: Protein | E26: Milk and Milk Products | F26: 1493 | G26: Food Composition Table for Use in Africa | H26: milk, cow, fluid, whole | I26: per 100g edible portion | J26: 79 | K26: 5.4 | L26: 3.8 | M26: 4.8 | N26: 0 | O26: 0.8 | P26: 143 | Q26: 0 | R26: 1
A27: Pal/Progresa | B27: Mexico | C27: corn | D27: Staples (coarse & fine) | E27: Cereals | F27: Tables of Composition of Food and Food Products | H27: corn, yellow grain | I27: per 100g edible portion | J27: 343 | K27: 69.55 | L27: 8.3 | M27: 4.08 | N27: 12.8 | O27: 1.2 | P27: 8 | Q27: 2.55 | R27: 0
A28: Nicaragua | B28: Central America | C28: corn | D28: Staples (coarse & fine) | E28: Cereals | F28: 13047 | G28: Tabla de Composicion de Alimentos de Centroamerica | H28: corn, yellow grain | I28: per 100g edible portion | J28: 365 | K28: 74.26 | L28: 9.42 | M28: 4.74 | N28: 7.3 | O28: 1.2 | P28: 7 | Q28: 2.71 | R28: 0 | AA28: =V28/1000 -> 0 | AB28: =W28/1000 -> 0 | AC28: =X28/1000 -> 0
A29: Philippines | B29: ASEAN | C29: corn | D29: Staples (coarse & fine) | E29: Cereals | F29: AAA38 | G29: ASEAN Food Composition Database | H29: Corn, whole-kernel raw | I29: per 100g edible portion | J29: 111 | K29: 21.1 | L29: 3.4 | M29: 1.4 | O29: 0.7 | P29: 10 | Q29: 1.7 | R29: 13 | AA29: =V29/1000 -> 0 | AB29: =W29/1000 -> 0 | AC29: =X29/1000 -> 0
A30: Uganda | B30: East Africa | C30: corn | D30: Staples (coarse & fine) | E30: Cereals | F30: 44 | G30: Food Composition Table for Use in Africa | H30: Whole kernel, dried, yellow | I30: per 100g edible portion | J30: 364 | K30: 73.6 | L30: 10 | M30: 4.8 | N30: 2 | O30: 1.2 | P30: 13 | Q30: 4.9 | R30: 4
A31: Pal/Progresa | B31: Mexico | C31: bread | D31: Staples (coarse & fine) | E31: Cereals | F31: Tables of Composition of Food and Food Products | H31: Wheat, sliced enriched bread | I31: per 100g edible portion | J31: 307 | K31: 58.37 | L31: 9.38 | O31: 1.83 | P31: 108 | Q31: 33.9 | R31: 0
A32: Nicaragua | B32: Central America | C32: bread | D32: Staples (coarse & fine) | E32: Cereals | F32: 14021 | G32: Tabla de Composicion de Alimentos de Centroamerica | I32: per 100g edible portion | J32: 266 | K32: 50.61 | L32: 7.64 | M32: 3.29 | N32: 2.4 | O32: 2.03 | P32: 151 | Q32: 3.74 | R32: 0 | AA32: =V32/1000 -> 0 | AB32: =W32/1000 -> 0 | AC32: =X32/1000 -> 0
A33: Philippines | B33: ASEAN | C33: bread | D33: Staples (coarse & fine) | E33: Cereals | F33: AAA19 | G33: ASEAN Food Composition Database | I33: per 100g edible portion | J33: 273 | K33: 41.3 | L33: 11.9 | M33: 5.4 | N33: 5.9 | O33: 2 | P33: 83 | Q33: 1.9 | AA33: =V33/1000 -> 0 | AB33: =W33/1000 -> 0 | AC33: =X33/1000 -> 0
A34: Uganda | B34: East Africa | C34: bread | D34: Staples (coarse & fine) | E34: Cereals | F34: 26 | G34: Food Composition Table for Use in Africa | H34: White Bread | I34: per 100g edible portion | J34: 261 | K34: 51.7 | L34: 7.7 | M34: 2 | N34: 0.3 | O34: 1.7 | P34: 37 | Q34: 1.7 | R34: 0
A35: Pal/Progresa | B35: Mexico | C35: rice | D35: Staples (coarse & fine) | E35: Cereals | F35: Tables of Composition of Food and Food Products | H35: milled grain in bulk | I35: per 100g edible portion | J35: 360 | K35: 78.1 | L35: 7.86 | M35: 0.57 | N35: 1.3 | O35: 0.75 | P35: 10.5 | Q35: 0.93 | R35: 0
A36: Nicaragua | B36: Central America | C36: rice | D36: Staples (coarse & fine) | E36: Cereals | F36: 13004 | G36: Tabla de Composicion de Alimentos de Centroamerica | H36: Rice White Medium grain unenriched raw | I36: per 100g edible portion | J36: 360 | K36: 79.34 | L36: 6.61 | M36: 0.58 | O36: 0.58 | P36: 9 | Q36: 0.8 | R36: 0 | AA36: =V36/1000 -> 0 | AB36: =W36/1000 -> 0 | AC36: =X36/1000 -> 0
A37: Philippines | B37: ASEAN | C37: rice | D37: Staples (coarse & fine) | E37: Cereals | F37: AAA65 | G37: ASEAN Food Composition Database | H37: white, polished, raw | I37: per 100g edible portion | J37: 354 | K37: 79.7 | L37: 6.8 | M37: 0.7 | N37: 0.6 | O37: 0.5 | P37: 19 | Q37: 1.2 | R37: 0 | AA37: =V37/1000 -> 0 | AB37: =W37/1000 -> 0 | AC37: =X37/1000 -> 0
A38: Uganda | B38: East Africa | C38: rice | D38: Staples (coarse & fine) | E38: Cereals | F38: 119 | G38: Food Composition Table for Use in Africa | H38: Rice, red, native, milled | I38: per 100g edible portion | J38: 366 | K38: 81.6 | L38: 6.3 | M38: 0.3 | N38: 0.2 | O38: 0.4 | P38: 22 | Q38: 1.7
